W0605 18:49:19.215989 3841043 /home/h3/irve354e/.conda/envs/universal-ner/lib/python3.9/site-packages/torch/distributed/run.py:793] 
W0605 18:49:19.215989 3841043 /home/h3/irve354e/.conda/envs/universal-ner/lib/python3.9/site-packages/torch/distributed/run.py:793] *****************************************
W0605 18:49:19.215989 3841043 /home/h3/irve354e/.conda/envs/universal-ner/lib/python3.9/site-packages/torch/distributed/run.py:793] Setting OMP_NUM_THREADS environment variable for each process to be 1 in default, to avoid your system being overloaded, please further tune the variable for optimal performance in your application as needed. 
W0605 18:49:19.215989 3841043 /home/h3/irve354e/.conda/envs/universal-ner/lib/python3.9/site-packages/torch/distributed/run.py:793] *****************************************
W0605 18:49:19.217167 2931158 /home/h3/irve354e/.conda/envs/universal-ner/lib/python3.9/site-packages/torch/distributed/run.py:793] 
W0605 18:49:19.217167 2931158 /home/h3/irve354e/.conda/envs/universal-ner/lib/python3.9/site-packages/torch/distributed/run.py:793] *****************************************
W0605 18:49:19.217167 2931158 /home/h3/irve354e/.conda/envs/universal-ner/lib/python3.9/site-packages/torch/distributed/run.py:793] Setting OMP_NUM_THREADS environment variable for each process to be 1 in default, to avoid your system being overloaded, please further tune the variable for optimal performance in your application as needed. 
W0605 18:49:19.217167 2931158 /home/h3/irve354e/.conda/envs/universal-ner/lib/python3.9/site-packages/torch/distributed/run.py:793] *****************************************
W0605 18:49:19.216770 2716503 /home/h3/irve354e/.conda/envs/universal-ner/lib/python3.9/site-packages/torch/distributed/run.py:793] 
W0605 18:49:19.216770 2716503 /home/h3/irve354e/.conda/envs/universal-ner/lib/python3.9/site-packages/torch/distributed/run.py:793] *****************************************
W0605 18:49:19.216770 2716503 /home/h3/irve354e/.conda/envs/universal-ner/lib/python3.9/site-packages/torch/distributed/run.py:793] Setting OMP_NUM_THREADS environment variable for each process to be 1 in default, to avoid your system being overloaded, please further tune the variable for optimal performance in your application as needed. 
W0605 18:49:19.216770 2716503 /home/h3/irve354e/.conda/envs/universal-ner/lib/python3.9/site-packages/torch/distributed/run.py:793] *****************************************
W0605 18:49:19.292953 998370 /home/h3/irve354e/.conda/envs/universal-ner/lib/python3.9/site-packages/torch/distributed/run.py:793] 
W0605 18:49:19.292953 998370 /home/h3/irve354e/.conda/envs/universal-ner/lib/python3.9/site-packages/torch/distributed/run.py:793] *****************************************
W0605 18:49:19.292953 998370 /home/h3/irve354e/.conda/envs/universal-ner/lib/python3.9/site-packages/torch/distributed/run.py:793] Setting OMP_NUM_THREADS environment variable for each process to be 1 in default, to avoid your system being overloaded, please further tune the variable for optimal performance in your application as needed. 
W0605 18:49:19.292953 998370 /home/h3/irve354e/.conda/envs/universal-ner/lib/python3.9/site-packages/torch/distributed/run.py:793] *****************************************
Traceback (most recent call last):
  File "/data/horse/ws/irve354e-energy_llm_ner/super_weights/src/train_lth_sw.py", line 13, in <module>
    from model import GPTConfig, GPT
ModuleNotFoundError: No module named 'model'
Traceback (most recent call last):
  File "/data/horse/ws/irve354e-energy_llm_ner/super_weights/src/train_lth_sw.py", line 13, in <module>
    from model import GPTConfig, GPT
ModuleNotFoundError: No module named 'model'
Traceback (most recent call last):
  File "/data/horse/ws/irve354e-energy_llm_ner/super_weights/src/train_lth_sw.py", line 13, in <module>
Traceback (most recent call last):
  File "/data/horse/ws/irve354e-energy_llm_ner/super_weights/src/train_lth_sw.py", line 13, in <module>
    from model import GPTConfig, GPT
ModuleNotFoundError: No module named 'model'
    from model import GPTConfig, GPT
ModuleNotFoundError: No module named 'model'
Traceback (most recent call last):
  File "/data/horse/ws/irve354e-energy_llm_ner/super_weights/src/train_lth_sw.py", line 13, in <module>
    from model import GPTConfig, GPT
ModuleNotFoundError: No module named 'model'
Traceback (most recent call last):
  File "/data/horse/ws/irve354e-energy_llm_ner/super_weights/src/train_lth_sw.py", line 13, in <module>
    from model import GPTConfig, GPT
ModuleNotFoundError: No module named 'model'
Traceback (most recent call last):
  File "/data/horse/ws/irve354e-energy_llm_ner/super_weights/src/train_lth_sw.py", line 13, in <module>
    from model import GPTConfig, GPT
ModuleNotFoundError: No module named 'model'
Traceback (most recent call last):
  File "/data/horse/ws/irve354e-energy_llm_ner/super_weights/src/train_lth_sw.py", line 13, in <module>
    from model import GPTConfig, GPT
ModuleNotFoundError: No module named 'model'
Traceback (most recent call last):
  File "/data/horse/ws/irve354e-energy_llm_ner/super_weights/src/train_lth_sw.py", line 13, in <module>
    from model import GPTConfig, GPT
ModuleNotFoundError: No module named 'model'
Traceback (most recent call last):
  File "/data/horse/ws/irve354e-energy_llm_ner/super_weights/src/train_lth_sw.py", line 13, in <module>
    from model import GPTConfig, GPT
ModuleNotFoundError: No module named 'model'
Traceback (most recent call last):
  File "/data/horse/ws/irve354e-energy_llm_ner/super_weights/src/train_lth_sw.py", line 13, in <module>
    from model import GPTConfig, GPT
ModuleNotFoundError: No module named 'model'
Traceback (most recent call last):
  File "/data/horse/ws/irve354e-energy_llm_ner/super_weights/src/train_lth_sw.py", line 13, in <module>
    from model import GPTConfig, GPT
ModuleNotFoundError: No module named 'model'
Traceback (most recent call last):
  File "/data/horse/ws/irve354e-energy_llm_ner/super_weights/src/train_lth_sw.py", line 13, in <module>
    from model import GPTConfig, GPT
ModuleNotFoundError: No module named 'model'
Traceback (most recent call last):
  File "/data/horse/ws/irve354e-energy_llm_ner/super_weights/src/train_lth_sw.py", line 13, in <module>
    from model import GPTConfig, GPT
ModuleNotFoundError: No module named 'model'
Traceback (most recent call last):
  File "/data/horse/ws/irve354e-energy_llm_ner/super_weights/src/train_lth_sw.py", line 13, in <module>
    from model import GPTConfig, GPT
ModuleNotFoundError: No module named 'model'
W0605 18:49:25.587566 3841043 /home/h3/irve354e/.conda/envs/universal-ner/lib/python3.9/site-packages/torch/distributed/elastic/multiprocessing/api.py:897] Sending process 3841061 closing signal SIGTERM
W0605 18:49:25.588638 3841043 /home/h3/irve354e/.conda/envs/universal-ner/lib/python3.9/site-packages/torch/distributed/elastic/multiprocessing/api.py:897] Sending process 3841062 closing signal SIGTERM
W0605 18:49:25.589127 3841043 /home/h3/irve354e/.conda/envs/universal-ner/lib/python3.9/site-packages/torch/distributed/elastic/multiprocessing/api.py:897] Sending process 3841063 closing signal SIGTERM
E0605 18:49:25.605129 3841043 /home/h3/irve354e/.conda/envs/universal-ner/lib/python3.9/site-packages/torch/distributed/elastic/multiprocessing/api.py:869] failed (exitcode: 1) local_rank: 0 (pid: 3841060) of binary: /home/irve354e/.conda/envs/universal-ner/bin/python
W0605 18:49:25.628216 998370 /home/h3/irve354e/.conda/envs/universal-ner/lib/python3.9/site-packages/torch/distributed/elastic/multiprocessing/api.py:897] Sending process 998430 closing signal SIGTERM
W0605 18:49:25.629252 998370 /home/h3/irve354e/.conda/envs/universal-ner/lib/python3.9/site-packages/torch/distributed/elastic/multiprocessing/api.py:897] Sending process 998431 closing signal SIGTERM
W0605 18:49:25.629712 998370 /home/h3/irve354e/.conda/envs/universal-ner/lib/python3.9/site-packages/torch/distributed/elastic/multiprocessing/api.py:897] Sending process 998433 closing signal SIGTERM
Traceback (most recent call last):
  File "/home/irve354e/.conda/envs/universal-ner/bin/torchrun", line 8, in <module>
    sys.exit(main())
  File "/home/irve354e/.conda/envs/universal-ner/lib/python3.9/site-packages/torch/distributed/elastic/multiprocessing/errors/__init__.py", line 355, in wrapper
    return f(*args, **kwargs)
  File "/home/irve354e/.conda/envs/universal-ner/lib/python3.9/site-packages/torch/distributed/run.py", line 919, in main
    run(args)
  File "/home/irve354e/.conda/envs/universal-ner/lib/python3.9/site-packages/torch/distributed/run.py", line 910, in run
    elastic_launch(
  File "/home/irve354e/.conda/envs/universal-ner/lib/python3.9/site-packages/torch/distributed/launcher/api.py", line 138, in __call__
    return launch_agent(self._config, self._entrypoint, list(args))
  File "/home/irve354e/.conda/envs/universal-ner/lib/python3.9/site-packages/torch/distributed/launcher/api.py", line 269, in launch_agent
    raise ChildFailedError(
torch.distributed.elastic.multiprocessing.errors.ChildFailedError: 
============================================================
train_lth_sw.py FAILED
------------------------------------------------------------
Failures:
  <NO_OTHER_FAILURES>
------------------------------------------------------------
Root Cause (first observed failure):
[0]:
  time      : 2025-06-05_18:49:25
  host      : i8018.alpha.hpc.tu-dresden.de
  rank      : 4 (local_rank: 0)
  exitcode  : 1 (pid: 3841060)
  error_file: <N/A>
  traceback : To enable traceback see: https://pytorch.org/docs/stable/elastic/errors.html
============================================================
E0605 18:49:25.661834 998370 /home/h3/irve354e/.conda/envs/universal-ner/lib/python3.9/site-packages/torch/distributed/elastic/multiprocessing/api.py:869] failed (exitcode: 1) local_rank: 2 (pid: 998432) of binary: /home/irve354e/.conda/envs/universal-ner/bin/python
Traceback (most recent call last):
  File "/home/irve354e/.conda/envs/universal-ner/bin/torchrun", line 8, in <module>
    sys.exit(main())
  File "/home/irve354e/.conda/envs/universal-ner/lib/python3.9/site-packages/torch/distributed/elastic/multiprocessing/errors/__init__.py", line 355, in wrapper
    return f(*args, **kwargs)
  File "/home/irve354e/.conda/envs/universal-ner/lib/python3.9/site-packages/torch/distributed/run.py", line 919, in main
    run(args)
  File "/home/irve354e/.conda/envs/universal-ner/lib/python3.9/site-packages/torch/distributed/run.py", line 910, in run
    elastic_launch(
  File "/home/irve354e/.conda/envs/universal-ner/lib/python3.9/site-packages/torch/distributed/launcher/api.py", line 138, in __call__
    return launch_agent(self._config, self._entrypoint, list(args))
  File "/home/irve354e/.conda/envs/universal-ner/lib/python3.9/site-packages/torch/distributed/launcher/api.py", line 269, in launch_agent
    raise ChildFailedError(
torch.distributed.elastic.multiprocessing.errors.ChildFailedError: 
============================================================
train_lth_sw.py FAILED
------------------------------------------------------------
Failures:
  <NO_OTHER_FAILURES>
------------------------------------------------------------
Root Cause (first observed failure):
[0]:
  time      : 2025-06-05_18:49:25
  host      : i8020.alpha.hpc.tu-dresden.de
  rank      : 14 (local_rank: 2)
  exitcode  : 1 (pid: 998432)
  error_file: <N/A>
  traceback : To enable traceback see: https://pytorch.org/docs/stable/elastic/errors.html
============================================================
E0605 18:49:25.698321 2931158 /home/h3/irve354e/.conda/envs/universal-ner/lib/python3.9/site-packages/torch/distributed/elastic/multiprocessing/api.py:869] failed (exitcode: 1) local_rank: 0 (pid: 2931172) of binary: /home/irve354e/.conda/envs/universal-ner/bin/python
Traceback (most recent call last):
  File "/home/irve354e/.conda/envs/universal-ner/bin/torchrun", line 8, in <module>
    sys.exit(main())
  File "/home/irve354e/.conda/envs/universal-ner/lib/python3.9/site-packages/torch/distributed/elastic/multiprocessing/errors/__init__.py", line 355, in wrapper
    return f(*args, **kwargs)
  File "/home/irve354e/.conda/envs/universal-ner/lib/python3.9/site-packages/torch/distributed/run.py", line 919, in main
    run(args)
  File "/home/irve354e/.conda/envs/universal-ner/lib/python3.9/site-packages/torch/distributed/run.py", line 910, in run
    elastic_launch(
  File "/home/irve354e/.conda/envs/universal-ner/lib/python3.9/site-packages/torch/distributed/launcher/api.py", line 138, in __call__
    return launch_agent(self._config, self._entrypoint, list(args))
  File "/home/irve354e/.conda/envs/universal-ner/lib/python3.9/site-packages/torch/distributed/launcher/api.py", line 269, in launch_agent
    raise ChildFailedError(
torch.distributed.elastic.multiprocessing.errors.ChildFailedError: 
============================================================
train_lth_sw.py FAILED
------------------------------------------------------------
Failures:
[1]:
  time      : 2025-06-05_18:49:25
  host      : i8017.alpha.hpc.tu-dresden.de
  rank      : 1 (local_rank: 1)
  exitcode  : 1 (pid: 2931173)
  error_file: <N/A>
  traceback : To enable traceback see: https://pytorch.org/docs/stable/elastic/errors.html
[2]:
  time      : 2025-06-05_18:49:25
  host      : i8017.alpha.hpc.tu-dresden.de
  rank      : 2 (local_rank: 2)
  exitcode  : 1 (pid: 2931174)
  error_file: <N/A>
  traceback : To enable traceback see: https://pytorch.org/docs/stable/elastic/errors.html
[3]:
  time      : 2025-06-05_18:49:25
  host      : i8017.alpha.hpc.tu-dresden.de
  rank      : 3 (local_rank: 3)
  exitcode  : 1 (pid: 2931175)
  error_file: <N/A>
  traceback : To enable traceback see: https://pytorch.org/docs/stable/elastic/errors.html
------------------------------------------------------------
Root Cause (first observed failure):
[0]:
  time      : 2025-06-05_18:49:25
  host      : i8017.alpha.hpc.tu-dresden.de
  rank      : 0 (local_rank: 0)
  exitcode  : 1 (pid: 2931172)
  error_file: <N/A>
  traceback : To enable traceback see: https://pytorch.org/docs/stable/elastic/errors.html
============================================================
W0605 18:49:25.759132 2716503 /home/h3/irve354e/.conda/envs/universal-ner/lib/python3.9/site-packages/torch/distributed/elastic/multiprocessing/api.py:897] Sending process 2716520 closing signal SIGTERM
E0605 18:49:25.792003 2716503 /home/h3/irve354e/.conda/envs/universal-ner/lib/python3.9/site-packages/torch/distributed/elastic/multiprocessing/api.py:869] failed (exitcode: 1) local_rank: 0 (pid: 2716518) of binary: /home/irve354e/.conda/envs/universal-ner/bin/python
Traceback (most recent call last):
  File "/home/irve354e/.conda/envs/universal-ner/bin/torchrun", line 8, in <module>
    sys.exit(main())
  File "/home/irve354e/.conda/envs/universal-ner/lib/python3.9/site-packages/torch/distributed/elastic/multiprocessing/errors/__init__.py", line 355, in wrapper
    return f(*args, **kwargs)
  File "/home/irve354e/.conda/envs/universal-ner/lib/python3.9/site-packages/torch/distributed/run.py", line 919, in main
    run(args)
  File "/home/irve354e/.conda/envs/universal-ner/lib/python3.9/site-packages/torch/distributed/run.py", line 910, in run
    elastic_launch(
  File "/home/irve354e/.conda/envs/universal-ner/lib/python3.9/site-packages/torch/distributed/launcher/api.py", line 138, in __call__
    return launch_agent(self._config, self._entrypoint, list(args))
  File "/home/irve354e/.conda/envs/universal-ner/lib/python3.9/site-packages/torch/distributed/launcher/api.py", line 269, in launch_agent
    raise ChildFailedError(
torch.distributed.elastic.multiprocessing.errors.ChildFailedError: 
============================================================
train_lth_sw.py FAILED
------------------------------------------------------------
Failures:
[1]:
  time      : 2025-06-05_18:49:25
  host      : i8019.alpha.hpc.tu-dresden.de
  rank      : 9 (local_rank: 1)
  exitcode  : 1 (pid: 2716519)
  error_file: <N/A>
  traceback : To enable traceback see: https://pytorch.org/docs/stable/elastic/errors.html
[2]:
  time      : 2025-06-05_18:49:25
  host      : i8019.alpha.hpc.tu-dresden.de
  rank      : 11 (local_rank: 3)
  exitcode  : 1 (pid: 2716521)
  error_file: <N/A>
  traceback : To enable traceback see: https://pytorch.org/docs/stable/elastic/errors.html
------------------------------------------------------------
Root Cause (first observed failure):
[0]:
  time      : 2025-06-05_18:49:25
  host      : i8019.alpha.hpc.tu-dresden.de
  rank      : 8 (local_rank: 0)
  exitcode  : 1 (pid: 2716518)
  error_file: <N/A>
  traceback : To enable traceback see: https://pytorch.org/docs/stable/elastic/errors.html
============================================================
srun: error: i8018: task 1: Exited with exit code 1
srun: error: i8017: task 0: Exited with exit code 1
srun: error: i8019: task 2: Exited with exit code 1
srun: error: i8020: task 3: Exited with exit code 1
